Workbook

Sheet Calculadora
A1: Calculadora de proyección de props (v0)
A3: Jugador | B3: Luka Dončić
A4: Rival | B4: Chicago Bulls
A5: Posición a usar (opcional)
A7: Posición usada | B7: =IF(B5<>"",B5,INDEX(Jugadores!$E$2:$E$583,MATCH(B3,Jugadores!$A$2:$A$583,0))) -> PG
A8: Equipo 2026-27 del jugador | B8: =INDEX(Jugadores!$C$2:$C$583,MATCH(B3,Jugadores!$A$2:$A$583,0)) -> LAL
A9: Continuidad del rival (0-1) | B9: =INDEX(Equipos!$C$2:$C$31,MATCH(B4,Equipos!$A$2:$A$31,0)) -> 0.627
A11: Stat | B11: Base con ajuste de rol | C11: Factor DvP rival | D11: Proyección | E11: Línea de la casa | F11: Proyección − línea | G11: Lado
A12: PTS | B12: =INDEX(Jugadores!$O$2:$O$583,MATCH($B$3,Jugadores!$A$2:$A$583,0)) -> 34.8 | C12: =INDEX(Factor_DvP!$H$2:$H$151,MATCH($B$4&"|"&$B$7,Factor_DvP!$A$2:$A$151,0)) -> 0.99005625 | D12: =ROUND(B12*C12,1) -> 34.5 | F12: =IF(E12="","",ROUND(D12-E12,1)) | G12: =IF(E12="","",IF(F12>=0,"Over","Under"))
A13: REB | B13: =INDEX(Jugadores!$P$2:$P$583,MATCH($B$3,Jugadores!$A$2:$A$583,0)) -> 7.93 | C13: =INDEX(Factor_DvP!$I$2:$I$151,MATCH($B$4&"|"&$B$7,Factor_DvP!$A$2:$A$151,0)) -> 0.99505 | D13: =ROUND(B13*C13,1) -> 7.9 | F13: =IF(E13="","",ROUND(D13-E13,1)) | G13: =IF(E13="","",IF(F13>=0,"Over","Under"))
A14: AST | B14: =INDEX(Jugadores!$Q$2:$Q$583,MATCH($B$3,Jugadores!$A$2:$A$583,0)) -> 8.7 | C14: =INDEX(Factor_DvP!$J$2:$J$151,MATCH($B$4&"|"&$B$7,Factor_DvP!$A$2:$A$151,0)) -> 1.0402295 | D14: =ROUND(B14*C14,1) -> 9 | E14: 8.5 | F14: =IF(E14="","",ROUND(D14-E14,1)) -> 0.5 | G14: =IF(E14="","",IF(F14>=0,"Over","Under")) -> Over
A15: PRA | B15: =SUM(B12:B14) -> 51.43 | C15: =ROUND(D15/B15,3) -> 0.999 | D15: =SUM(D12:D14) -> 51.4 | F15: =IF(E15="","",ROUND(D15-E15,1)) | G15: =IF(E15="","",IF(F15>=0,"Over","Under"))
A17: OJO: la diferencia con la línea NO es una ventaja por sí sola. Falta compararla con la variabilidad real del jugador y con la cuota.
A18: Celdas amarillas = las que puedes cambiar. Los parámetros están en la hoja Parametros.
A20: PROBABILIDAD DEL MODELO vs PROBABILIDAD DE LA CASA
A21: Escribe la línea arriba (columna E) y aquí las cuotas DECIMALES del over y del under. Las filas de ejemplo (asistencias) son solo una demostración: bórralas o cámbialas.
A22: Stat | B22: Proyección | C22: Línea | D22: Cuota over | E22: Cuota under | F22: P modelo Over | G22: P modelo Under | H22: Implícita over (con margen) | I22: Implícita over (sin margen) | J22: Ventaja vs justa | K22: EV over (por unidad) | L22: EV under (por unidad) | M22: Lectura
A23: PTS | B23: =D12 -> 34.5 | C23: =IF(E12="","",E12) | F23: =IF(OR($C23="",$B23=""),"",1-NORMDIST(INT($C23)+0.5,$B23,Parametros!$B$6*$B23,TRUE())) | G23: =IF(OR($C23="",$B23=""),"",NORMDIST(-INT(-$C23)-0.5,$B23,Parametros!$B$6*$B23,TRUE())) | H23: =IF($D23="","",1/$D23) | I23: =IF(OR($D23="",$E23=""),"",(1/$D23)/((1/$D23)+(1/$E23))) | J23: =IF(OR($F23="",$I23=""),"",$F23-$I23) | K23: =IF(OR($F23="",$D23="",$G23=""),"",$F23*($D23-1)-$G23) | L23: =IF(OR($G23="",$E23="",$F23=""),"",$G23*($E23-1)-$F23) | M23: =IF(OR($K23="",$L23=""),"",IF(MAX($K23,$L23)>=Parametros!$B$10,IF($K23>=$L23,"Over","Under"),"Sin ventaja suficiente"))
A24: REB | B24: =D13 -> 7.9 | C24: =IF(E13="","",E13) | F24: =IF(OR($C24="",$B24=""),"",1-BETADIST(1/Parametros!$B$7,$B24/(Parametros!$B$7-1),INT($C24)+1)) | G24: =IF(OR($C24="",$B24=""),"",BETADIST(1/Parametros!$B$7,$B24/(Parametros!$B$7-1),-INT(-$C24))) | H24: =IF($D24="","",1/$D24) | I24: =IF(OR($D24="",$E24=""),"",(1/$D24)/((1/$D24)+(1/$E24))) | J24: =IF(OR($F24="",$I24=""),"",$F24-$I24) | K24: =IF(OR($F24="",$D24="",$G24=""),"",$F24*($D24-1)-$G24) | L24: =IF(OR($G24="",$E24="",$F24=""),"",$G24*($E24-1)-$F24) | M24: =IF(OR($K24="",$L24=""),"",IF(MAX($K24,$L24)>=Parametros!$B$10,IF($K24>=$L24,"Over","Under"),"Sin ventaja suficiente"))
A25: AST | B25: =D14 -> 9 | C25: =IF(E14="","",E14) -> 8.5 | D25: 1.87 | E25: 1.95 | F25: =IF(OR($C25="",$B25=""),"",1-BETADIST(1/Parametros!$B$8,$B25/(Parametros!$B$8-1),INT($C25)+1)) -> 0.52258191 | G25: =IF(OR($C25="",$B25=""),"",BETADIST(1/Parametros!$B$8,$B25/(Parametros!$B$8-1),-INT(-$C25))) -> 0.47741809 | H25: =IF($D25="","",1/$D25) -> 0.53475936 | I25: =IF(OR($D25="",$E25=""),"",(1/$D25)/((1/$D25)+(1/$E25))) -> 0.5104712 | J25: =IF(OR($F25="",$I25=""),"",$F25-$I25) -> 0.012110706 | K25: =IF(OR($F25="",$D25="",$G25=""),"",$F25*($D25-1)-$G25) -> -0.022771828 | L25: =IF(OR($G25="",$E25="",$F25=""),"",$G25*($E25-1)-$F25) -> -0.069034724 | M25: =IF(OR($K25="",$L25=""),"",IF(MAX($K25,$L25)>=Parametros!$B$10,IF($K25>=$L25,"Over","Under"),"Sin ventaja suficiente")) -> Sin ventaja suficiente
A26: PRA | B26: =D15 -> 51.4 | C26: =IF(E15="","",E15) | F26: =IF(OR($C26="",$B26=""),"",1-NORMDIST(INT($C26)+0.5,$B26,Parametros!$B$9*$B26,TRUE())) | G26: =IF(OR($C26="",$B26=""),"",NORMDIST(-INT(-$C26)-0.5,$B26,Parametros!$B$9*$B26,TRUE())) | H26: =IF($D26="","",1/$D26) | I26: =IF(OR($D26="",$E26=""),"",(1/$D26)/((1/$D26)+(1/$E26))) | J26: =IF(OR($F26="",$I26=""),"",$F26-$I26) | K26: =IF(OR($F26="",$D26="",$G26=""),"",$F26*($D26-1)-$G26) | L26: =IF(OR($G26="",$E26="",$F26=""),"",$G26*($E26-1)-$F26) | M26: =IF(OR($K26="",$L26=""),"",IF(MAX($K26,$L26)>=Parametros!$B$10,IF($K26>=$L26,"Over","Under"),"Sin ventaja suficiente"))
A28: Cómo leerlo
A29: • P modelo = probabilidad (según el modelo) de que el jugador supere / se quede debajo de la línea. En línea entera (ej. 9) la diferencia hasta 100% es 'push' (te devuelven la apuesta).
A30: • Implícita con margen = 1 / cuota. Es el punto de equilibrio: necesitas acertar MÁS que eso para ganar dinero a largo plazo.
A31: • Implícita sin margen = lo que la casa 'cree' de verdad, quitando su comisión. Sirve para medir la ventaja (columna J).
A32: • EV = ganancia esperada por cada unidad apostada = P × (cuota − 1) − (1 − P). Si es negativa, esa apuesta pierde dinero a largo plazo aunque la ventaja de la columna J sea positiva.
A33: • El modelo NO está calibrado todavía: usa la hoja Registro para anotar lo que pasa y comprobar si sus probabilidades se cumplen.
A35: Conversor de cuota americana → decimal
A36: Cuota americana (ej. -115 o +120) | B36: -115
A37: Cuota decimal | B37: =IF(B36="","",IF(B36>0,1+B36/100,1+100/ABS(B36))) -> 1.8695652

Sheet Parametros
A1: Parámetro | B1: Valor | C1: Qué hace
A2: lambda_PTS | B2: 0.7 | C2: Cuánto del 'sube/baja' del rival en puntos se mantiene (0=ignorar defensa, 1=confiar 100%). Supuesto inicial, falta calibrar.
A3: lambda_REB | B3: 0.6 | C3: Igual, para rebotes.
A4: lambda_AST | B4: 0.5 | C4: Igual, para asistencias (las más ruidosas por posición).
A5: Tope_factor | B5: 0.12 | C5: El factor DvP nunca mueve la proyección más de ±12%.
A6: sd_PTS | B6: 0.3 | C6: Variación típica de los puntos de un jugador = 30% de su promedio (supuesto genérico; se mide con registros por partido).
A7: var_REB | B7: 1.3 | C7: Rebotes: varianza = 1,3 × promedio (supuesto).
A8: var_AST | B8: 1.4 | C8: Asistencias: varianza = 1,4 × promedio (supuesto).
A9: sd_PRA | B9: 0.25 | C9: Variación típica de puntos+rebotes+asistencias = 25% de su promedio (supuesto).
A10: EV_minimo | B10: 0.05 | C10: Esperanza de ganancia mínima (por unidad apostada) para marcar una jugada. Alta a propósito: el modelo aún no está calibrado.
A12: Fórmula del factor | C12: Factor = 1 + límite( continuidad_rival × lambda × (valor_rival − media_posición) / media_posición )
A13: Ajuste de rol | C13: Columnas adj_* de la hoja Jugadores (calculadas fuera de la hoja): DAMP=0.30, CAP=±6%, ARR_W=0.60. Reparte la producción de los que se fueron entre los que se quedan, según su margen de minutos.
A14: Pendiente de calibrar | C14: lambda y los parámetros de rol son supuestos de partida. Se calibran con histórico por partido (backtest), no a ojo.

Sheet Equipos
A1: Equipo | B1: Abrev | C1: Continuidad | D1: Retenido_25-26 | E1: Retenido_26-27 | F1: Principales salidas | G1: Principales llegadas
A2: Atlanta Hawks | B2: ATL | C2: 0.738 | D2: 0.689 | E2: 0.788 | F2: Trae Young; Kristaps Porziņģis; Jonathan Kuminga | G2: Aaron Wiggins; Devin Carter; Luguentz Dort
A3: Boston Celtics | B3: BOS | C3: 0.753 | D3: 0.723 | E3: 0.783 | F3: Jaylen Brown; Anfernee Simons; Nikola Vučević | G3: Paul George; Mitchell Robinson; Mike Conley
A4: Brooklyn Nets | B4: BRK | C4: 0.822 | D4: 0.797 | E4: 0.848 | F4: Cam Thomas; Nic Claxton; Ziaire Williams | G4: Julius Randle; Moritz Wagner; Keon Ellis
A5: Charlotte Hornets | B5: CHO | C5: 0.628 | D5: 0.641 | E5: 0.614 | F5: LaMelo Ball; Miles Bridges; Collin Sexton | G5: Grayson Allen; Naz Reid; Dennis Schröder
A6: Chicago Bulls | B6: CHI | C6: 0.627 | D6: 0.522 | E6: 0.733 | F6: Coby White; Collin Sexton; Nikola Vučević | G6: Norman Powell; Nic Claxton; Buddy Hield
A7: Cleveland Cavaliers | B7: CLE | C7: 0.73 | D7: 0.614 | E7: 0.847 | F7: Darius Garland; De'Andre Hunter; Max Strus | G7: Peyton Watson; Cam Whitmore
A8: Dallas Mavericks | B8: DAL | C8: 0.726 | D8: 0.631 | E8: 0.821 | F8: Brandon Williams; Klay Thompson; Marvin Bagley III | G8: Santi Aldama; Zaccharie Risacher; Marcus Sasser
A9: Denver Nuggets | B9: DEN | C9: 0.806 | D9: 0.832 | E9: 0.779 | F9: Peyton Watson; Tim Hardaway Jr. | G9: DeMar DeRozan; Marvin Bagley III; KJ Simpson
A10: Detroit Pistons | B10: DET | C10: 0.704 | D10: 0.689 | E10: 0.719 | F10: Tobias Harris; Isaiah Stewart; Jaden Ivey | G10: John Collins; Isaiah Joe; Taurean Prince
A11: Golden State Warriors | B11: GSW | C11: 0.893 | D11: 0.843 | E11: 0.943 | F11: Jonathan Kuminga; Buddy Hield; Quinten Post | G11: Brandon Williams
A12: Houston Rockets | B12: HOU | C12: 0.861 | D12: 0.882 | E12: 0.841 | F12: Josh Okogie; Dorian Finney-Smith | G12: Marcus Smart; Bogdan Bogdanović
A13: Indiana Pacers | B13: IND | C13: 0.819 | D13: 0.741 | E13: 0.898 | F13: Bennedict Mathurin; Micah Potter; Isaiah Jackson | G13: Kelly Oubre Jr.; Larry Nance Jr.
... A21: New York Knicks | B21: NYK | C21: 0.93 | D21: 0.929 | E21: 0.93 | F21: Mitchell Robinson | G21: Andre Drummond
A22: Oklahoma City Thunder | B22: OKC | C22: 0.873 | D22: 0.745 | E22: 1 | F22: Isaiah Joe; Aaron Wiggins; Luguentz Dort
A23: Orlando Magic | B23: ORL | C23: 0.915 | D23: 0.917 | E23: 0.913 | F23: Moritz Wagner; Tyus Jones | G23: Nikola Vučević
A24: Philadelphia 76ers | B24: PHI | C24: 0.583 | D24: 0.58 | E24: 0.586 | F24: Paul George; Kelly Oubre Jr.; Quentin Grimes | G24: Jaylen Brown; LeBron James; Anfernee Simons
A25: Phoenix Suns | B25: PHO | C25: 0.83 | D25: 0.825 | E25: 0.835 | F25: Grayson Allen; Royce O'Neale | G25: Miles Bridges; Luke Kennard
A26: Portland Trail Blazers | B26: POR | C26: 0.779 | D26: 0.766 | E26: 0.792 | F26: Jerami Grant; Kris Murray; Matisse Thybulle | G26: Ja Morant; Micah Potter; Branden Carlson
A27: Sacramento Kings | B27: SAC | C27: 0.903 | D27: 0.806 | E27: 1 | F27: DeMar DeRozan; Dennis Schröder; Devin Carter
A28: San Antonio Spurs | B28: SAS | C28: 0.926 | D28: 0.952 | E28: 0.901 | F28: Jeremy Sochan | G28: Tobias Harris
A29: Toronto Raptors | B29: TOR | C29: 0.734 | D29: 0.685 | E29: 0.782 | F29: Brandon Ingram; Sandro Mamukelashvili; Gradey Dick | G29: Kawhi Leonard; Kyle Anderson
A30: Utah Jazz | B30: UTA | C30: 0.841 | D30: 0.779 | E30: 0.903 | F30: Walker Kessler; Cody Williams; Kyle Anderson | G30: Jaxson Hayes; Josh Okogie; Josh Green
A31: Washington Wizards | B31: WAS | C31: 0.841 | D31: 0.769 | E31: 0.912 | F31: CJ McCollum; Jaden Hardy; Marvin Bagley III | G31: Deandre Ayton; Tre Mann

Sheet DvP
A1: Equipo | B1: Posicion | C1: Puntos | D1: Asistencias | E1: Rebotes | F1: Triples | G1: Robos | H1: Rank_Puntos | I1: Rank_Asistencias | J1: Rank_Rebotes | K1: Rank_Triples | L1: Rank_Robos | M1: Bloqueos | N1: Rank_Bloqueos
A2: Atlanta Hawks | B2: PG | C2: 25.14 | D2: 8.9 | E2: 5.97 | F2: 3.26 | G2: 1.88 | H2: 14 | I2: 11 | J2: 22 | K2: 11 | L2: 16 | M2: 0.61 | N2: 10
A3: Brooklyn Nets | B3: PG | C3: 23.93 | D3: 9.01 | E3: 6.49 | F3: 2.9 | G3: 2.02 | H3: 23 | I3: 10 | J3: 11 | K3: 25 | L3: 6 | M3: 0.5 | N3: 24
A4: Boston Celtics | B4: PG | C4: 24.24 | D4: 8.51 | E4: 5.74 | F4: 3.58 | G4: 1.53 | H4: 21 | I4: 17 | J4: 25 | K4: 5 | L4: 30 | M4: 0.5 | N4: 24
A5: Charlotte Hornets | B5: PG | C5: 24.2 | D5: 8.03 | E5: 5.7 | F5: 2.99 | G5: 1.77 | H5: 22 | I5: 21 | J5: 28 | K5: 20 | L5: 20 | M5: 0.56 | N5: 19
A6: Chicago Bulls | B6: PG | C6: 24.33 | D6: 9.59 | E6: 6.15 | F6: 3.49 | G6: 1.98 | H6: 18 | I6: 1 | J6: 15 | K6: 7 | L6: 10 | M6: 0.57 | N6: 18
A7: Cleveland Cavaliers | B7: PG | C7: 23.89 | D7: 8.72 | E7: 5.73 | F7: 3.27 | G7: 1.74 | H7: 24 | I7: 14 | J7: 26 | K7: 10 | L7: 22 | M7: 0.5 | N7: 24
A8: Dallas Mavericks | B8: PG | C8: 26.21 | D8: 9.18 | E8: 7.1 | F8: 2.96 | G8: 2 | H8: 7 | I8: 5 | J8: 1 | K8: 22 | L8: 8 | M8: 0.64 | N8: 5
A9: Denver Nuggets | B9: PG | C9: 23.77 | D9: 8.71 | E9: 6.35 | F9: 2.98 | G9: 1.64 | H9: 25 | I9: 15 | J9: 13 | K9: 21 | L9: 28 | M9: 0.73 | N9: 2
A10: Detroit Pistons | B10: PG | C10: 22.78 | D10: 7.33 | E10: 5.8 | F10: 2.74 | G10: 2.13 | H10: 29 | I10: 30 | J10: 24 | K10: 30 | L10: 3 | M10: 0.64 | N10: 5
A11: Golden State Warriors | B11: PG | C11: 26.14 | D11: 7.92 | E11: 5.98 | F11: 3.22 | G11: 2.14 | H11: 8 | I11: 23 | J11: 21 | K11: 14 | L11: 2 | M11: 0.53 | N11: 22
A12: Houston Rockets | B12: PG | C12: 23.76 | D12: 7.57 | E12: 5.72 | F12: 3.15 | G12: 1.74 | H12: 26 | I12: 27 | J12: 27 | K12: 17 | L12: 22 | M12: 0.59 | N12: 15
A13: Indiana Pacers | B13: PG | C13: 26.28 | D13: 8.73 | E13: 7.03 | F13: 2.93 | G13: 2.02 | H13: 5 | I13: 13 | J13: 2 | K13: 24 | L13: 6 | M13: 0.61 | N13: 10
... A151: Washington Wizards | B151: C | C151: 26.59 | D151: 4.41 | E151: 16.42 | F151: 1.56 | G151: 1.5 | H151: 1 | I151: 8 | J151: 1 | K151: 7 | L151: 12 | M151: 2.56 | N151: 3

Sheet Factor_DvP
A1: Clave | B1: Equipo rival | C1: Pos | D1: Continuidad rival | E1: Dev_PTS | F1: Dev_REB | G1: Dev_AST | H1: Factor_PTS | I1: Factor_REB | J1: Factor_AST
A2: =B2&"|"&C2 -> Atlanta Hawks|PG | B2: =DvP!A2 -> Atlanta Hawks | C2: =DvP!B2 -> PG | D2: =INDEX(Equipos!$C$2:$C$31,MATCH(B2,Equipos!$A$2:$A$31,0)) -> 0.738 | E2: =(DvP!C2-AVERAGEIFS(DvP!$C$2:$C$151,DvP!$B$2:$B$151,C2))/AVERAGEIFS(DvP!$C$2:$C$151,DvP!$B$2:$B$151,C2) -> 0.0098818993 | F2: =(DvP!E2-AVERAGEIFS(DvP!$E$2:$E$151,DvP!$B$2:$B$151,C2))/AVERAGEIFS(DvP!$E$2:$E$151,DvP!$B$2:$B$151,C2) -> -0.042041078 | G2: =(DvP!D2-AVERAGEIFS(DvP!$D$2:$D$151,DvP!$B$2:$B$151,C2))/AVERAGEIFS(DvP!$D$2:$D$151,DvP!$B$2:$B$151,C2) -> 0.047140952 | H2: =1+MAX(-Parametros!$B$5,MIN(Parametros!$B$5,D2*Parametros!$B$2*E2)) -> 1.005105 | I2: =1+MAX(-Parametros!$B$5,MIN(Parametros!$B$5,D2*Parametros!$B$3*F2)) -> 0.98138421 | J2: =1+MAX(-Parametros!$B$5,MIN(Parametros!$B$5,D2*Parametros!$B$4*G2)) -> 1.017395
A3: =B3&"|"&C3 -> Brooklyn Nets|PG | B3: =DvP!A3 -> Brooklyn Nets | C3: =DvP!B3 -> PG | D3: =INDEX(Equipos!$C$2:$C$31,MATCH(B3,Equipos!$A$2:$A$31,0)) -> 0.822 | E3: =(DvP!C3-AVERAGEIFS(DvP!$C$2:$C$151,DvP!$B$2:$B$151,C3))/AVERAGEIFS(DvP!$C$2:$C$151,DvP!$B$2:$B$151,C3) -> -0.038724191 | F3: =(DvP!E3-AVERAGEIFS(DvP!$E$2:$E$151,DvP!$B$2:$B$151,C3))/AVERAGEIFS(DvP!$E$2:$E$151,DvP!$B$2:$B$151,C3) -> 0.04139923 | G3: =(DvP!D3-AVERAGEIFS(DvP!$D$2:$D$151,DvP!$B$2:$B$151,C3))/AVERAGEIFS(DvP!$D$2:$D$151,DvP!$B$2:$B$151,C3) -> 0.060083144 | H3: =1+MAX(-Parametros!$B$5,MIN(Parametros!$B$5,D3*Parametros!$B$2*E3)) -> 0.9777181 | I3: =1+MAX(-Parametros!$B$5,MIN(Parametros!$B$5,D3*Parametros!$B$3*F3)) -> 1.0204181 | J3: =1+MAX(-Parametros!$B$5,MIN(Parametros!$B$5,D3*Parametros!$B$4*G3)) -> 1.0246942
A4: =B4&"|"&C4 -> Boston Celtics|PG | B4: =DvP!A4 -> Boston Celtics | C4: =DvP!B4 -> PG | D4: =INDEX(Equipos!$C$2:$C$31,MATCH(B4,Equipos!$A$2:$A$31,0)) -> 0.753 | E4: =(DvP!C4-AVERAGEIFS(DvP!$C$2:$C$151,DvP!$B$2:$B$151,C4))/AVERAGEIFS(DvP!$C$2:$C$151,DvP!$B$2:$B$151,C4) -> -0.026271391 | F4: =(DvP!E4-AVERAGEIFS(DvP!$E$2:$E$151,DvP!$B$2:$B$151,C4))/AVERAGEIFS(DvP!$E$2:$E$151,DvP!$B$2:$B$151,C4) -> -0.078947368 | G4: =(DvP!D4-AVERAGEIFS(DvP!$D$2:$D$151,DvP!$B$2:$B$151,C4))/AVERAGEIFS(DvP!$D$2:$D$151,DvP!$B$2:$B$151,C4) -> 0.0012550004 | H4: =1+MAX(-Parametros!$B$5,MIN(Parametros!$B$5,D4*Parametros!$B$2*E4)) -> 0.98615235 | I4: =1+MAX(-Parametros!$B$5,MIN(Parametros!$B$5,D4*Parametros!$B$3*F4)) -> 0.96433158 | J4: =1+MAX(-Parametros!$B$5,MIN(Parametros!$B$5,D4*Parametros!$B$4*G4)) -> 1.0004725
A5: =B5&"|"&C5 -> Charlotte Hornets|PG | B5: =DvP!A5 -> Charlotte Hornets | C5: =DvP!B5 -> PG | D5: =INDEX(Equipos!$C$2:$C$31,MATCH(B5,Equipos!$A$2:$A$31,0)) -> 0.628 | E5: =(DvP!C5-AVERAGEIFS(DvP!$C$2:$C$151,DvP!$B$2:$B$151,C5))/AVERAGEIFS(DvP!$C$2:$C$151,DvP!$B$2:$B$151,C5) -> -0.027878204 | F5: =(DvP!E5-AVERAGEIFS(DvP!$E$2:$E$151,DvP!$B$2:$B$151,C5))/AVERAGEIFS(DvP!$E$2:$E$151,DvP!$B$2:$B$151,C5) -> -0.085365854 | G5: =(DvP!D5-AVERAGEIFS(DvP!$D$2:$D$151,DvP!$B$2:$B$151,C5))/AVERAGEIFS(DvP!$D$2:$D$151,DvP!$B$2:$B$151,C5) -> -0.055220017 | H5: =1+MAX(-Parametros!$B$5,MIN(Parametros!$B$5,D5*Parametros!$B$2*E5)) -> 0.98774474 | I5: =1+MAX(-Parametros!$B$5,MIN(Parametros!$B$5,D5*Parametros!$B$3*F5)) -> 0.96783415 | J5: =1+MAX(-Parametros!$B$5,MIN(Parametros!$B$5,D5*Parametros!$B$4*G5)) -> 0.98266091
A6: =B6&"|"&C6 -> Chicago Bulls|PG | B6: =DvP!A6 -> Chicago Bulls | C6: =DvP!B6 -> PG | D6: =INDEX(Equipos!$C$2:$C$31,MATCH(B6,Equipos!$A$2:$A$31,0)) -> 0.627 | E6: =(DvP!C6-AVERAGEIFS(DvP!$C$2:$C$151,DvP!$B$2:$B$151,C6))/AVERAGEIFS(DvP!$C$2:$C$151,DvP!$B$2:$B$151,C6) -> -0.022656062 | F6: =(DvP!E6-AVERAGEIFS(DvP!$E$2:$E$151,DvP!$B$2:$B$151,C6))/AVERAGEIFS(DvP!$E$2:$E$151,DvP!$B$2:$B$151,C6) -> -0.013157895 | G6: =(DvP!D6-AVERAGEIFS(DvP!$D$2:$D$151,DvP!$B$2:$B$151,C6))/AVERAGEIFS(DvP!$D$2:$D$151,DvP!$B$2:$B$151,C6) -> 0.12832379 | H6: =1+MAX(-Parametros!$B$5,MIN(Parametros!$B$5,D6*Parametros!$B$2*E6)) -> 0.99005625 | I6: =1+MAX(-Parametros!$B$5,MIN(Parametros!$B$5,D6*Parametros!$B$3*F6)) -> 0.99505 | J6: =1+MAX(-Parametros!$B$5,MIN(Parametros!$B$5,D6*Parametros!$B$4*G6)) -> 1.0402295
A7: =B7&"|"&C7 -> Cleveland Cavaliers|PG | B7: =DvP!A7 -> Cleveland Cavaliers | C7: =DvP!B7 -> PG | D7: =INDEX(Equipos!$C$2:$C$31,MATCH(B7,Equipos!$A$2:$A$31,0)) -> 0.73 | E7: =(DvP!C7-AVERAGEIFS(DvP!$C$2:$C$151,DvP!$B$2:$B$151,C7))/AVERAGEIFS(DvP!$C$2:$C$151,DvP!$B$2:$B$151,C7) -> -0.040331003 | F7: =(DvP!E7-AVERAGEIFS(DvP!$E$2:$E$151,DvP!$B$2:$B$151,C7))/AVERAGEIFS(DvP!$E$2:$E$151,DvP!$B$2:$B$151,C7) -> -0.08055199 | G7: =(DvP!D7-AVERAGEIFS(DvP!$D$2:$D$151,DvP!$B$2:$B$151,C7))/AVERAGEIFS(DvP!$D$2:$D$151,DvP!$B$2:$B$151,C7) -> 0.025962821 | H7: =1+MAX(-Parametros!$B$5,MIN(Parametros!$B$5,D7*Parametros!$B$2*E7)) -> 0.97939086 | I7: =1+MAX(-Parametros!$B$5,MIN(Parametros!$B$5,D7*Parametros!$B$3*F7)) -> 0.96471823 | J7: =1+MAX(-Parametros!$B$5,MIN(Parametros!$B$5,D7*Parametros!$B$4*G7)) -> 1.0094764
A8: =B8&"|"&C8 -> Dallas Mavericks|PG | B8: =DvP!A8 -> Dallas Mavericks | C8: =DvP!B8 -> PG | D8: =INDEX(Equipos!$C$2:$C$31,MATCH(B8,Equipos!$A$2:$A$31,0)) -> 0.726 | E8: =(DvP!C8-AVERAGEIFS(DvP!$C$2:$C$151,DvP!$B$2:$B$151,C8))/AVERAGEIFS(DvP!$C$2:$C$151,DvP!$B$2:$B$151,C8) -> 0.052864144 | F8: =(DvP!E8-AVERAGEIFS(DvP!$E$2:$E$151,DvP!$B$2:$B$151,C8))/AVERAGEIFS(DvP!$E$2:$E$151,DvP!$B$2:$B$151,C8) -> 0.13928113 | G8: =(DvP!D8-AVERAGEIFS(DvP!$D$2:$D$151,DvP!$B$2:$B$151,C8))/AVERAGEIFS(DvP!$D$2:$D$151,DvP!$B$2:$B$151,C8) -> 0.080084713 | H8: =1+MAX(-Parametros!$B$5,MIN(Parametros!$B$5,D8*Parametros!$B$2*E8)) -> 1.0268656 | I8: =1+MAX(-Parametros!$B$5,MIN(Parametros!$B$5,D8*Parametros!$B$3*F8)) -> 1.0606709 | J8: =1+MAX(-Parametros!$B$5,MIN(Parametros!$B$5,D8*Parametros!$B$4*G8)) -> 1.0290708
A9: =B9&"|"&C9 -> Denver Nuggets|PG | B9: =DvP!A9 -> Denver Nuggets | C9: =DvP!B9 -> PG | D9: =INDEX(Equipos!$C$2:$C$31,MATCH(B9,Equipos!$A$2:$A$31,0)) -> 0.806 | E9: =(DvP!C9-AVERAGEIFS(DvP!$C$2:$C$151,DvP!$B$2:$B$151,C9))/AVERAGEIFS(DvP!$C$2:$C$151,DvP!$B$2:$B$151,C9) -> -0.045151442 | F9: =(DvP!E9-AVERAGEIFS(DvP!$E$2:$E$151,DvP!$B$2:$B$151,C9))/AVERAGEIFS(DvP!$E$2:$E$151,DvP!$B$2:$B$151,C9) -> 0.018934531 | G9: =(DvP!D9-AVERAGEIFS(DvP!$D$2:$D$151,DvP!$B$2:$B$151,C9))/AVERAGEIFS(DvP!$D$2:$D$151,DvP!$B$2:$B$151,C9) -> 0.024786258 | H9: =1+MAX(-Parametros!$B$5,MIN(Parametros!$B$5,D9*Parametros!$B$2*E9)) -> 0.97452556 | I9: =1+MAX(-Parametros!$B$5,MIN(Parametros!$B$5,D9*Parametros!$B$3*F9)) -> 1.0091567 | J9: =1+MAX(-Parametros!$B$5,MIN(Parametros!$B$5,D9*Parametros!$B$4*G9)) -> 1.0099889
A10: =B10&"|"&C10 -> Detroit Pistons|PG | B10: =DvP!A10 -> Detroit Pistons | C10: =DvP!B10 -> PG | D10: =INDEX(Equipos!$C$2:$C$31,MATCH(B10,Equipos!$A$2:$A$31,0)) -> 0.704 | E10: =(DvP!C10-AVERAGEIFS(DvP!$C$2:$C$151,DvP!$B$2:$B$151,C10))/AVERAGEIFS(DvP!$C$2:$C$151,DvP!$B$2:$B$151,C10) -> -0.084920061 | F10: =(DvP!E10-AVERAGEIFS(DvP!$E$2:$E$151,DvP!$B$2:$B$151,C10))/AVERAGEIFS(DvP!$E$2:$E$151,DvP!$B$2:$B$151,C10) -> -0.069319641 | G10: =(DvP!D10-AVERAGEIFS(DvP!$D$2:$D$151,DvP!$B$2:$B$151,C10))/AVERAGEIFS(DvP!$D$2:$D$151,DvP!$B$2:$B$151,C10) -> -0.13757942 | H10: =1+MAX(-Parametros!$B$5,MIN(Parametros!$B$5,D10*Parametros!$B$2*E10)) -> 0.95815139 | I10: =1+MAX(-Parametros!$B$5,MIN(Parametros!$B$5,D10*Parametros!$B$3*F10)) -> 0.97071938 | J10: =1+MAX(-Parametros!$B$5,MIN(Parametros!$B$5,D10*Parametros!$B$4*G10)) -> 0.95157204
A11: =B11&"|"&C11 -> Golden State Warriors|PG | B11: =DvP!A11 -> Golden State Warriors | C11: =DvP!B11 -> PG | D11: =INDEX(Equipos!$C$2:$C$31,MATCH(B11,Equipos!$A$2:$A$31,0)) -> 0.893 | E11: =(DvP!C11-AVERAGEIFS(DvP!$C$2:$C$151,DvP!$B$2:$B$151,C11))/AVERAGEIFS(DvP!$C$2:$C$151,DvP!$B$2:$B$151,C11) -> 0.050052221 | F11: =(DvP!E11-AVERAGEIFS(DvP!$E$2:$E$151,DvP!$B$2:$B$151,C11))/AVERAGEIFS(DvP!$E$2:$E$151,DvP!$B$2:$B$151,C11) -> -0.040436457 | G11: =(DvP!D11-AVERAGEIFS(DvP!$D$2:$D$151,DvP!$B$2:$B$151,C11))/AVERAGEIFS(DvP!$D$2:$D$151,DvP!$B$2:$B$151,C11) -> -0.068162209 | H11: =1+MAX(-Parametros!$B$5,MIN(Parametros!$B$5,D11*Parametros!$B$2*E11)) -> 1.0312876 | I11: =1+MAX(-Parametros!$B$5,MIN(Parametros!$B$5,D11*Parametros!$B$3*F11)) -> 0.97833415 | J11: =1+MAX(-Parametros!$B$5,MIN(Parametros!$B$5,D11*Parametros!$B$4*G11)) -> 0.96956557
A12: =B12&"|"&C12 -> Houston Rockets|PG | B12: =DvP!A12 -> Houston Rockets | C12: =DvP!B12 -> PG | D12: =INDEX(Equipos!$C$2:$C$31,MATCH(B12,Equipos!$A$2:$A$31,0)) -> 0.861 | E12: =(DvP!C12-AVERAGEIFS(DvP!$C$2:$C$151,DvP!$B$2:$B$151,C12))/AVERAGEIFS(DvP!$C$2:$C$151,DvP!$B$2:$B$151,C12) -> -0.045553145 | F12: =(DvP!E12-AVERAGEIFS(DvP!$E$2:$E$151,DvP!$B$2:$B$151,C12))/AVERAGEIFS(DvP!$E$2:$E$151,DvP!$B$2:$B$151,C12) -> -0.082156611 | G12: =(DvP!D12-AVERAGEIFS(DvP!$D$2:$D$151,DvP!$B$2:$B$151,C12))/AVERAGEIFS(DvP!$D$2:$D$151,DvP!$B$2:$B$151,C12) -> -0.10934191 | H12: =1+MAX(-Parametros!$B$5,MIN(Parametros!$B$5,D12*Parametros!$B$2*E12)) -> 0.97254512 | I12: =1+MAX(-Parametros!$B$5,MIN(Parametros!$B$5,D12*Parametros!$B$3*F12)) -> 0.95755789 | J12: =1+MAX(-Parametros!$B$5,MIN(Parametros!$B$5,D12*Parametros!$B$4*G12)) -> 0.95292831
A13: =B13&"|"&C13 -> Indiana Pacers|PG | B13: =DvP!A13 -> Indiana Pacers | C13: =DvP!B13 -> PG | D13: =INDEX(Equipos!$C$2:$C$31,MATCH(B13,Equipos!$A$2:$A$31,0)) -> 0.819 | E13: =(DvP!C13-AVERAGEIFS(DvP!$C$2:$C$151,DvP!$B$2:$B$151,C13))/AVERAGEIFS(DvP!$C$2:$C$151,DvP!$B$2:$B$151,C13) -> 0.055676067 | F13: =(DvP!E13-AVERAGEIFS(DvP!$E$2:$E$151,DvP!$B$2:$B$151,C13))/AVERAGEIFS(DvP!$E$2:$E$151,DvP!$B$2:$B$151,C13) -> 0.12804878 | G13: =(DvP!D13-AVERAGEIFS(DvP!$D$2:$D$151,DvP!$B$2:$B$151,C13))/AVERAGEIFS(DvP!$D$2:$D$151,DvP!$B$2:$B$151,C13) -> 0.027139383 | H13: =1+MAX(-Parametros!$B$5,MIN(Parametros!$B$5,D13*Parametros!$B$2*E13)) -> 1.0319191 | I13: =1+MAX(-Parametros!$B$5,MIN(Parametros!$B$5,D13*Parametros!$B$3*F13)) -> 1.0629232 | J13: =1+MAX(-Parametros!$B$5,MIN(Parametros!$B$5,D13*Parametros!$B$4*G13)) -> 1.0111136
... A151: =B151&"|"&C151 -> Washington Wizards|C | B151: =DvP!A151 -> Washington Wizards | C151: =DvP!B151 -> C | D151: =INDEX(Equipos!$C$2:$C$31,MATCH(B151,Equipos!$A$2:$A$31,0)) -> 0.841 | E151: =(DvP!C151-AVERAGEIFS(DvP!$C$2:$C$151,DvP!$B$2:$B$151,C151))/AVERAGEIFS(DvP!$C$2:$C$151,DvP!$B$2:$B$151,C151) -> 0.20072251 | F151: =(DvP!E151-AVERAGEIFS(DvP!$E$2:$E$151,DvP!$B$2:$B$151,C151))/AVERAGEIFS(DvP!$E$2:$E$151,DvP!$B$2:$B$151,C151) -> 0.14175783 | G151: =(DvP!D151-AVERAGEIFS(DvP!$D$2:$D$151,DvP!$B$2:$B$151,C151))/AVERAGEIFS(DvP!$D$2:$D$151,DvP!$B$2:$B$151,C151) -> 0.078943076 | H151: =1+MAX(-Parametros!$B$5,MIN(Parametros!$B$5,D151*Parametros!$B$2*E151)) -> 1.1181653 | I151: =1+MAX(-Parametros!$B$5,MIN(Parametros!$B$5,D151*Parametros!$B$3*F151)) -> 1.071531 | J151: =1+MAX(-Parametros!$B$5,MIN(Parametros!$B$5,D151*Parametros!$B$4*G151)) -> 1.0331956

Sheet Jugadores
A1: Jugador | B1: Equipo_25-26 | C1: Equipo_26-27 | D1: Movimiento | E1: Pos | F1: Pos_alt | G1: Confianza_pos | H1: MIN | I1: PTS | J1: REB | K1: AST | L1: adj_PTS | M1: adj_REB | N1: adj_AST | O1: PTS_base | P1: REB_base | Q1: AST_base
A2: Luka Dončić | B2: LAL | C2: LAL | D2: Sin movimiento reportado | E2: PG | G2: manual | H2: 35.8 | I2: 33.5 | J2: 7.7 | K2: 8.3 | L2: 1.302 | M2: 0.225 | N2: 0.395 | O2: =ROUND(I2+L2,2) -> 34.8 | P2: =ROUND(J2+M2,2) -> 7.93 | Q2: =ROUND(K2+N2,2) -> 8.7
A3: Shai Gilgeous-Alexander | B3: OKC | C3: OKC | D3: Sin movimiento reportado | E3: PG | G3: manual | H3: 33.2 | I3: 31.1 | J3: 4.3 | K3: 6.6 | L3: 1.202 | M3: 0.147 | N3: 0.15 | O3: =ROUND(I3+L3,2) -> 32.3 | P3: =ROUND(J3+M3,2) -> 4.45 | Q3: =ROUND(K3+N3,2) -> 6.75
A4: Anthony Edwards | B4: MIN | C4: MIN | D4: Sin movimiento reportado | E4: SG | G4: manual | H4: 35 | I4: 28.8 | J4: 5 | K4: 3.7 | L4: 0.55 | M4: 0.175 | N4: 0.11 | O4: =ROUND(I4+L4,2) -> 29.35 | P4: =ROUND(J4+M4,2) -> 5.18 | Q4: =ROUND(K4+N4,2) -> 3.81
A5: Jaylen Brown | B5: BOS | C5: PHI | D5: Cambió de equipo | E5: SF | F5: SG | G5: manual | H5: 34.4 | I5: 28.7 | J5: 6.9 | K5: 5.1 | L5: 0 | M5: 0 | N5: 0 | O5: =ROUND(I5+L5,2) -> 28.7 | P5: =ROUND(J5+M5,2) -> 6.9 | Q5: =ROUND(K5+N5,2) -> 5.1
A6: Tyrese Maxey | B6: PHI | C6: PHI | D6: Sin movimiento reportado | E6: PG | F6: SG | G6: manual | H6: 38 | I6: 28.3 | J6: 4.1 | K6: 6.6 | L6: 0.221 | M6: 0.069 | N6: 0.052 | O6: =ROUND(I6+L6,2) -> 28.52 | P6: =ROUND(J6+M6,2) -> 4.17 | Q6: =ROUND(K6+N6,2) -> 6.65
A7: Kawhi Leonard | B7: LAC | C7: TOR | D7: Cambió de equipo | E7: SF | G7: manual | H7: 32.1 | I7: 27.9 | J7: 6.4 | K7: 3.6 | L7: 0 | M7: 0 | N7: 0 | O7: =ROUND(I7+L7,2) -> 27.9 | P7: =ROUND(J7+M7,2) -> 6.4 | Q7: =ROUND(K7+N7,2) -> 3.6
A8: Donovan Mitchell | B8: CLE | C8: CLE | D8: Renovó | E8: SG | G8: manual | H8: 33.5 | I8: 27.9 | J8: 4.5 | K8: 5.7 | L8: 1.674 | M8: 0.245 | N8: 0.342 | O8: =ROUND(I8+L8,2) -> 29.57 | P8: =ROUND(J8+M8,2) -> 4.75 | Q8: =ROUND(K8+N8,2) -> 6.04
A9: Nikola Jokić | B9: DEN | C9: DEN | D9: Sin movimiento reportado | E9: C | G9: manual | H9: 34.8 | I9: 27.7 | J9: 12.9 | K9: 10.7 | L9: 0.154 | M9: 0.008 | N9: -0.117 | O9: =ROUND(I9+L9,2) -> 27.85 | P9: =ROUND(J9+M9,2) -> 12.91 | Q9: =ROUND(K9+N9,2) -> 10.58
A10: Giannis Antetokounmpo | B10: MIL | C10: MIA | D10: Cambió de equipo | E10: PF | G10: manual | H10: 28.9 | I10: 27.6 | J10: 9.8 | K10: 5.4 | L10: 0 | M10: 0 | N10: 0 | O10: =ROUND(I10+L10,2) -> 27.6 | P10: =ROUND(J10+M10,2) -> 9.8 | Q10: =ROUND(K10+N10,2) -> 5.4
A11: Joel Embiid | B11: PHI | C11: PHI | D11: Sin movimiento reportado | E11: C | G11: manual | H11: 31.6 | I11: 26.9 | J11: 7.7 | K11: 3.9 | L11: 0.883 | M11: 0.462 | N11: 0.129 | O11: =ROUND(I11+L11,2) -> 27.78 | P11: =ROUND(J11+M11,2) -> 8.16 | Q11: =ROUND(K11+N11,2) -> 4.03
A12: Lauri Markkanen | B12: UTA | C12: UTA | D12: Sin movimiento reportado | E12: PF | F12: C | G12: manual | H12: 34.4 | I12: 26.7 | J12: 6.9 | K12: 2.1 | L12: 0.611 | M12: 0.206 | N12: 0.066 | O12: =ROUND(I12+L12,2) -> 27.31 | P12: =ROUND(J12+M12,2) -> 7.11 | Q12: =ROUND(K12+N12,2) -> 2.17
A13: Stephen Curry | B13: GSW | C13: GSW | D13: Renovó | E13: PG | G13: manual | H13: 30.9 | I13: 26.6 | J13: 3.6 | K13: 4.7 | L13: 0.573 | M13: 0.118 | N13: 0.075 | O13: =ROUND(I13+L13,2) -> 27.17 | P13: =ROUND(J13+M13,2) -> 3.72 | Q13: =ROUND(K13+N13,2) -> 4.78
A14: Devin Booker | B14: PHO | C14: PHO | D14: Sin movimiento reportado | E14: SG | G14: manual | H14: 33.5 | I14: 26.1 | J14: 3.9 | K14: 6 | L14: 0.289 | M14: 0.028 | N14: 0.098 | O14: =ROUND(I14+L14,2) -> 26.39 | P14: =ROUND(J14+M14,2) -> 3.93 | Q14: =ROUND(K14+N14,2) -> 6.1
A15: Jalen Brunson | B15: NYK | C15: NYK | D15: Sin movimiento reportado | E15: PG | G15: manual | H15: 35 | I15: 26 | J15: 3.3 | K15: 6.8 | L15: 0.051 | M15: 0.041 | N15: 0.003 | O15: =ROUND(I15+L15,2) -> 26.05 | P15: =ROUND(J15+M15,2) -> 3.34 | Q15: =ROUND(K15+N15,2) -> 6.8
A16: Kevin Durant | B16: HOU | C16: HOU | D16: Sin movimiento reportado | E16: PF | F16: SF | G16: manual | H16: 36.4 | I16: 26 | J16: 5.5 | K16: 4.8 | L16: -0.045 | M16: 0.017 | N16: -0.028 | O16: =ROUND(I16+L16,2) -> 25.96 | P16: =ROUND(J16+M16,2) -> 5.52 | Q16: =ROUND(K16+N16,2) -> 4.77
A17: Jamal Murray | B17: DEN | C17: DEN | D17: Sin movimiento reportado | E17: PG | G17: manual | H17: 35.4 | I17: 25.4 | J17: 4.4 | K17: 7.1 | L17: 0.125 | M17: 0.002 | N17: -0.069 | O17: =ROUND(I17+L17,2) -> 25.53 | P17: =ROUND(J17+M17,2) -> 4.4 | Q17: =ROUND(K17+N17,2) -> 7.03
A18: Victor Wembanyama | B18: SAS | C18: SAS | D18: Renovó | E18: C | G18: manual | H18: 29.2 | I18: 25 | J18: 11.5 | K18: 3.1 | L18: -0.187 | M18: -0.025 | N18: -0.013 | O18: =ROUND(I18+L18,2) -> 24.81 | P18: =ROUND(J18+M18,2) -> 11.48 | Q18: =ROUND(K18+N18,2) -> 3.09
A19: Deni Avdija | B19: POR | C19: POR | D19: Sin movimiento reportado | E19: SF | F19: PF | G19: manual | H19: 33.3 | I19: 24.2 | J19: 6.9 | K19: 6.7 | L19: 0.273 | M19: 0.054 | N19: -0.051 | O19: =ROUND(I19+L19,2) -> 24.47 | P19: =ROUND(J19+M19,2) -> 6.95 | Q19: =ROUND(K19+N19,2) -> 6.65
A20: Michael Porter Jr. | B20: BRK | C20: BRK | D20: Sin movimiento reportado | E20: SF | F20: PF | G20: manual | H20: 32.5 | I20: 24.2 | J20: 7.1 | K20: 3 | L20: 0.512 | M20: 0.108 | N20: 0.062 | O20: =ROUND(I20+L20,2) -> 24.71 | P20: =ROUND(J20+M20,2) -> 7.21 | Q20: =ROUND(K20+N20,2) -> 3.06
A21: Pascal Siakam | B21: IND | C21: IND | D21: Sin movimiento reportado | E21: PF | G21: manual | H21: 33.2 | I21: 24 | J21: 6.6 | K21: 3.8 | L21: 0.851 | M21: 0.279 | N21: 0.104 | O21: =ROUND(I21+L21,2) -> 24.85 | P21: =ROUND(J21+M21,2) -> 6.88 | Q21: =ROUND(K21+N21,2) -> 3.9
A22: Cade Cunningham | B22: DET | C22: DET | D22: Sin movimiento reportado | E22: PG | G22: manual | H22: 33.9 | I22: 23.9 | J22: 5.5 | K22: 9.9 | L22: 0.604 | M22: 0.12 | N22: 0.333 | O22: =ROUND(I22+L22,2) -> 24.5 | P22: =ROUND(J22+M22,2) -> 5.62 | Q22: =ROUND(K22+N22,2) -> 10.23
A23: James Harden | B23: CLE | C23: CLE | D23: Renovó | E23: PG | F23: SG | G23: manual | H23: 34.8 | I23: 23.6 | J23: 4.8 | K23: 8 | L23: 1.222 | M23: 0.209 | N23: 0.48 | O23: =ROUND(I23+L23,2) -> 24.82 | P23: =ROUND(J23+M23,2) -> 5.01 | Q23: =ROUND(K23+N23,2) -> 8.48
A24: Keyonte George | B24: UTA | C24: UTA | D24: Renovó | E24: PG | G24: manual | H24: 33.1 | I24: 23.6 | J24: 3.7 | K24: 6.1 | L24: 0.666 | M24: 0.136 | N24: 0.235 | O24: =ROUND(I24+L24,2) -> 24.27 | P24: =ROUND(J24+M24,2) -> 3.84 | Q24: =ROUND(K24+N24,2) -> 6.34
A25: Austin Reaves | B25: LAL | C25: LAL | D25: Renovó | E25: SG | F25: PG | G25: manual | H25: 34.5 | I25: 23.3 | J25: 4.7 | K25: 5.5 | L25: 1.186 | M25: 0.18 | N25: 0.33 | O25: =ROUND(I25+L25,2) -> 24.49 | P25: =ROUND(J25+M25,2) -> 4.88 | Q25: =ROUND(K25+N25,2) -> 5.83
A26: Jalen Johnson | B26: ATL | C26: ATL | D26: Sin movimiento reportado | E26: PF | F26: SF | G26: manual | H26: 35.2 | I26: 22.5 | J26: 10.3 | K26: 7.9 | L26: 0.972 | M26: 0.229 | N26: 0.321 | O26: =ROUND(I26+L26,2) -> 23.47 | P26: =ROUND(J26+M26,2) -> 10.53 | Q26: =ROUND(K26+N26,2) -> 8.22
A27: Paolo Banchero | B27: ORL | C27: ORL | D27: Sin movimiento reportado | E27: PF | G27: manual | H27: 34.8 | I27: 22.2 | J27: 8.4 | K27: 5.2 | L27: 0.015 | M27: -0.012 | N27: 0.023 | O27: =ROUND(I27+L27,2) -> 22.22 | P27: =ROUND(J27+M27,2) -> 8.39 | Q27: =ROUND(K27+N27,2) -> 5.22
A28: Jayson Tatum | B28: BOS | C28: BOS | D28: Sin movimiento reportado | E28: SF | F28: PF | G28: manual | H28: 32.6 | I28: 21.8 | J28: 10 | K28: 5.3 | L28: 1.308 | M28: 0.282 | N28: 0.216 | O28: =ROUND(I28+L28,2) -> 23.11 | P28: =ROUND(J28+M28,2) -> 10.28 | Q28: =ROUND(K28+N28,2) -> 5.52
A29: Norman Powell | B29: MIA | C29: CHI | D29: Cambió de equipo | E29: SG | G29: manual | H29: 29.6 | I29: 21.7 | J29: 3.5 | K29: 2.5 | L29: 0 | M29: 0 | N29: 0 | O29: =ROUND(I29+L29,2) -> 21.7 | P29: =ROUND(J29+M29,2) -> 3.5 | Q29: =ROUND(K29+N29,2) -> 2.5
A30: Brandon Ingram | B30: TOR | C30: LAC | D30: Cambió de equipo | E30: SF | G30: manual | H30: 33.8 | I30: 21.5 | J30: 5.6 | K30: 3.7 | L30: 0 | M30: 0 | N30: 0 | O30: =ROUND(I30+L30,2) -> 21.5 | P30: =ROUND(J30+M30,2) -> 5.6 | Q30: =ROUND(K30+N30,2) -> 3.7
A31: Trey Murphy III | B31: NOP | C31: NOP | D31: Sin movimiento reportado | E31: SF | F31: SG | G31: manual | H31: 35.5 | I31: 21.5 | J31: 5.7 | K31: 3.8 | L31: 0.077 | M31: 0.054 | N31: 0.038 | O31: =ROUND(I31+L31,2) -> 21.58 | P31: =ROUND(J31+M31,2) -> 5.75 | Q31: =ROUND(K31+N31,2) -> 3.84
A32: Julius Randle | B32: MIN | C32: BRK | D32: Cambió de equipo | E32: PF | G32: manual | H32: 33 | I32: 21.1 | J32: 6.7 | K32: 5 | L32: 0 | M32: 0 | N32: 0 | O32: =ROUND(I32+L32,2) -> 21.1 | P32: =ROUND(J32+M32,2) -> 6.7 | Q32: =ROUND(K32+N32,2) -> 5
A33: Cooper Flagg | B33: DAL | C33: DAL | D33: Sin movimiento reportado | E33: SF | F33: PF | G33: manual | H33: 33.5 | I33: 21 | J33: 6.7 | K33: 4.5 | L33: 1.26 | M33: 0.195 | N33: 0.27 | O33: =ROUND(I33+L33,2) -> 22.26 | P33: =ROUND(J33+M33,2) -> 6.9 | Q33: =ROUND(K33+N33,2) -> 4.77
A34: Zion Williamson | B34: NOP | C34: NOP | D34: Sin movimiento reportado | E34: PF | G34: manual | H34: 29.7 | I34: 21 | J34: 5.7 | K34: 3.2 | L34: 0.171 | M34: 0.124 | N34: 0.074 | O34: =ROUND(I34+L34,2) -> 21.17 | P34: =ROUND(J34+M34,2) -> 5.82 | Q34: =ROUND(K34+N34,2) -> 3.27
A35: LeBron James | B35: LAL | C35: PHI | D35: Cambió de equipo | E35: SF | F35: PF | G35: manual | H35: 33.2 | I35: 20.9 | J35: 6.1 | K35: 7.2 | L35: 0 | M35: 0 | N35: 0 | O35: =ROUND(I35+L35,2) -> 20.9 | P35: =ROUND(J35+M35,2) -> 6.1 | Q35: =ROUND(K35+N35,2) -> 7.2
A36: Nickeil Alexander-Walker | B36: ATL | C36: ATL | D36: Sin movimiento reportado | E36: SG | F36: PG | G36: manual | H36: 33.4 | I36: 20.8 | J36: 3.4 | K36: 3.7 | L36: 1.235 | M36: 0.104 | N36: 0.207 | O36: =ROUND(I36+L36,2) -> 22.04 | P36: =ROUND(J36+M36,2) -> 3.5 | Q36: =ROUND(K36+N36,2) -> 3.91
A37: Shaedon Sharpe | B37: POR | C37: POR | D37: Sin movimiento reportado | E37: SG | G37: manual | H37: 29.4 | I37: 20.8 | J37: 4.3 | K37: 2.6 | L37: 0.372 | M37: 0.053 | N37: -0.032 | O37: =ROUND(I37+L37,2) -> 21.17 | P37: =ROUND(J37+M37,2) -> 4.35 | Q37: =ROUND(K37+N37,2) -> 2.57
A38: Franz Wagner | B38: ORL | C38: ORL | D38: Sin movimiento reportado | E38: SF | G38: manual | H38: 30 | I38: 20.6 | J38: 5.2 | K38: 3.3 | L38: 0.026 | M38: -0.014 | N38: 0.028 | O38: =ROUND(I38+L38,2) -> 20.63 | P38: =ROUND(J38+M38,2) -> 5.19 | Q38: =ROUND(K38+N38,2) -> 3.33
A39: Tyler Herro | B39: MIA | C39: MIL | D39: Cambió de equipo | E39: SG | G39: manual | H39: 31.3 | I39: 20.5 | J39: 4.8 | K39: 4.1 | L39: 0 | M39: 0 | N39: 0 | O39: =ROUND(I39+L39,2) -> 20.5 | P39: =ROUND(J39+M39,2) -> 4.8 | Q39: =ROUND(K39+N39,2) -> 4.1
A40: Anthony Davis | B40: DAL | C40: DAL | D40: Sin movimiento reportado | E40: C | F40: PF | G40: manual | H40: 31.3 | I40: 20.4 | J40: 11.1 | K40: 2.8 | L40: 1.224 | M40: 0.432 | N40: 0.168 | O40: =ROUND(I40+L40,2) -> 21.62 | P40: =ROUND(J40+M40,2) -> 11.53 | Q40: =ROUND(K40+N40,2) -> 2.97
...

Sheet Registro
A1: Registro de jugadas (para medir si el modelo acierta lo que dice)
A2: Anota cada jugada que analices (aunque no apuestes). Pega la 'P modelo' de ese lado, y al terminar el partido escribe el resultado real.
A4: Jugadas resueltas | B4: =COUNT(I9:I508) -> 0 | D4: Error de Brier (menor = mejor; 0,25 = igual que lanzar una moneda) | F4: =IF(B4=0,"",AVERAGE(J9:J508))
A5: % de acierto real | B5: =IF(B4=0,"",AVERAGE(I9:I508)) | D5: Si % de acierto real ≈ prob. media del modelo, está bien calibrado.
A6: Prob. media que daba el modelo | B6: =IF(B4=0,"",SUMPRODUCT(ISNUMBER(I9:I508)*G9:G508)/B4)
A8: Fecha | B8: Jugador | C8: Stat | D8: Lado (Over/Under) | E8: Línea | F8: Cuota decimal | G8: P modelo (de ese lado) | H8: Resultado real | I8: Acertó (1/0) | J8: Brier
I9: =IF(OR(H9="",E9="",D9=""),"",IF(H9=E9,"push",IF(D9="Over",IF(H9>E9,1,0),IF(H9<E9,1,0)))) | J9: =IF(AND(ISNUMBER(I9),G9<>""),(G9-I9)^2,"")
I10: =IF(OR(H10="",E10="",D10=""),"",IF(H10=E10,"push",IF(D10="Over",IF(H10>E10,1,0),IF(H10<E10,1,0)))) | J10: =IF(AND(ISNUMBER(I10),G10<>""),(G10-I10)^2,"")
I11: =IF(OR(H11="",E11="",D11=""),"",IF(H11=E11,"push",IF(D11="Over",IF(H11>E11,1,0),IF(H11<E11,1,0)))) | J11: =IF(AND(ISNUMBER(I11),G11<>""),(G11-I11)^2,"")
I12: =IF(OR(H12="",E12="",D12=""),"",IF(H12=E12,"push",IF(D12="Over",IF(H12>E12,1,0),IF(H12<E12,1,0)))) | J12: =IF(AND(ISNUMBER(I12),G12<>""),(G12-I12)^2,"")
I13: =IF(OR(H13="",E13="",D13=""),"",IF(H13=E13,"push",IF(D13="Over",IF(H13>E13,1,0),IF(H13<E13,1,0)))) | J13: =IF(AND(ISNUMBER(I13),G13<>""),(G13-I13)^2,"")
I14: =IF(OR(H14="",E14="",D14=""),"",IF(H14=E14,"push",IF(D14="Over",IF(H14>E14,1,0),IF(H14<E14,1,0)))) | J14: =IF(AND(ISNUMBER(I14),G14<>""),(G14-I14)^2,"")
I15: =IF(OR(H15="",E15="",D15=""),"",IF(H15=E15,"push",IF(D15="Over",IF(H15>E15,1,0),IF(H15<E15,1,0)))) | J15: =IF(AND(ISNUMBER(I15),G15<>""),(G15-I15)^2,"")
I16: =IF(OR(H16="",E16="",D16=""),"",IF(H16=E16,"push",IF(D16="Over",IF(H16>E16,1,0),IF(H16<E16,1,0)))) | J16: =IF(AND(ISNUMBER(I16),G16<>""),(G16-I16)^2,"")
I17: =IF(OR(H17="",E17="",D17=""),"",IF(H17=E17,"push",IF(D17="Over",IF(H17>E17,1,0),IF(H17<E17,1,0)))) | J17: =IF(AND(ISNUMBER(I17),G17<>""),(G17-I17)^2,"")
I18: =IF(OR(H18="",E18="",D18=""),"",IF(H18=E18,"push",IF(D18="Over",IF(H18>E18,1,0),IF(H18<E18,1,0)))) | J18: =IF(AND(ISNUMBER(I18),G18<>""),(G18-I18)^2,"")
I19: =IF(OR(H19="",E19="",D19=""),"",IF(H19=E19,"push",IF(D19="Over",IF(H19>E19,1,0),IF(H19<E19,1,0)))) | J19: =IF(AND(ISNUMBER(I19),G19<>""),(G19-I19)^2,"")
I20: =IF(OR(H20="",E20="",D20=""),"",IF(H20=E20,"push",IF(D20="Over",IF(H20>E20,1,0),IF(H20<E20,1,0)))) | J20: =IF(AND(ISNUMBER(I20),G20<>""),(G20-I20)^2,"")
... I508: =IF(OR(H508="",E508="",D508=""),"",IF(H508=E508,"push",IF(D508="Over",IF(H508>E508,1,0),IF(H508<E508,1,0)))) | J508: =IF(AND(ISNUMBER(I508),G508<>""),(G508-I508)^2,"")
